#VRML_SIM R2023b utf8

EXTERNPROTO "https://raw.githubusercontent.com/cyberbotics/webots/R2023b/projects/objects/backgrounds/protos/TexturedBackground.proto"
EXTERNPROTO "https://raw.githubusercontent.com/cyberbotics/webots/R2023b/projects/objects/backgrounds/protos/TexturedBackgroundLight.proto"
EXTERNPROTO "https://raw.githubusercontent.com/cyberbotics/webots/R2023b/projects/objects/floors/protos/RectangleArena.proto"

WorldInfo {
}
Viewpoint {
  orientation -0.7017831954713536 0.0020339030602545636 0.712387682229527 3.137467414860133
  position 0.08288311779617819 -0.07282775187500917 1.9517716278958919
}
TexturedBackground {
}
TexturedBackgroundLight {
}
RectangleArena {
}
Robot {
  translation 0.216933 0.329198 0.0496764
  rotation -0.0007027333980611514 3.3571109888518484e-07 -0.9999997530827989 0.003257923814577818
  children [
    HingeJoint {
      jointParameters HingeJointParameters {
        position 45.53165552285993
        anchor -0.06 -0.06 0
      }
      device [
        RotationalMotor {
          name "wheel1"
        }
      ]
      endPoint DEF wheel1 Solid {
        translation -0.06 -0.06 0
        rotation -0.5731786847469884 -0.5856022345853804 -0.5731807901529166 4.201120721550211
        children [
          DEF wheel Shape {
            appearance PBRAppearance {
            }
            geometry Cylinder {
              height 0.02
              radius 0.05
            }
          }
        ]
        name "wheel1"
        boundingObject USE wheel
        physics DEF wheel_ph Physics {
        }
      }
    }
    HingeJoint {
      jointParameters HingeJointParameters {
        position 57.94657323107512
        anchor 0.06 -0.06 0
      }
      device [
        RotationalMotor {
          name "wheel2"
        }
      ]
      endPoint DEF wheel2 Solid {
        translation 0.06 -0.06 0
        rotation -0.5410888942016318 -0.6437728374784079 -0.5410908817349028 4.28555958653261
        children [
          DEF wheel Shape {
            appearance PBRAppearance {
            }
            geometry Cylinder {
              height 0.02
              radius 0.05
            }
          }
        ]
        name "wheel2"
        boundingObject USE wheel
        physics DEF wheel_ph Physics {
        }
      }
    }
    HingeJoint {
      jointParameters HingeJointParameters {
        position 50.65119638872214
        anchor -0.06 0.06 0
      }
      device [
        RotationalMotor {
          name "wheel3"
        }
      ]
      endPoint DEF wheel3 Solid {
        translation -0.06 0.06 0
        rotation 0.18823674082725103 0.9639157631759508 0.18823743225952372 1.6075430979791852
        children [
          DEF wheel Shape {
            appearance PBRAppearance {
            }
            geometry Cylinder {
              height 0.02
              radius 0.05
            }
          }
        ]
        name "wheel3"
        boundingObject USE wheel
        physics DEF wheel_ph Physics {
        }
      }
    }
    HingeJoint {
      jointParameters HingeJointParameters {
        position 52.82703845360128
        anchor 0.06 0.06 0
      }
      device [
        RotationalMotor {
          name "wheel4"
        }
      ]
      endPoint DEF wheel4 Solid {
        translation 0.06 0.06 0
        rotation 0.6918685063678122 0.2064769145386298 0.6918708359650521 2.7343629179488103
        children [
          DEF wheel Shape {
            appearance PBRAppearance {
            }
            geometry Cylinder {
              height 0.02
              radius 0.05
            }
          }
        ]
        name "wheel4"
        boundingObject USE wheel
        physics DEF wheel_ph Physics {
        }
      }
    }
    DEF body Shape {
      appearance PBRAppearance {
        baseColor 0.4 0.6 0.9
        roughness 0.5
        metalness 0.5
      }
      geometry Box {
        size 0.1 0.2 0.05
      }
    }
  ]
  boundingObject USE body
  physics Physics {
  }
  controller "S_pattern"
}
