#VRML_SIM R2023b utf8

EXTERNPROTO "https://raw.githubusercontent.com/cyberbotics/webots/R2023b/projects/objects/backgrounds/protos/TexturedBackground.proto"
EXTERNPROTO "https://raw.githubusercontent.com/cyberbotics/webots/R2023b/projects/objects/backgrounds/protos/TexturedBackgroundLight.proto"
IMPORTABLE EXTERNPROTO "https://raw.githubusercontent.com/cyberbotics/webots/R2023b/projects/objects/floors/protos/Floor.proto"

WorldInfo {
  basicTimeStep 16
}
Viewpoint {
  orientation 0.2039394214808927 0.07850035542877248 -0.9758311362954121 2.422955999005014
  position 1.9290249125683492 1.6784589662899903 1.1648156240210854
}
TexturedBackground {
}
TexturedBackgroundLight {
}
Floor {
  size 2 2
}
Robot {
  translation -0.10203717283324738 0.05255538312083539 0.039860482586743046
  rotation 1.0736744354235452e-07 -2.9697199369256058e-08 0.9999999999999938 1.6099987774603988
  children [
    DEF DS_LEFT DistanceSensor {
      translation 0.1 0.03 0
      rotation 0 0 1 0.3
      children [
        Shape {
          appearance PBRAppearance {
            baseColor 0.184314 0.596078 0.847059
            roughness 1
            metalness 0
          }
          geometry Box {
            size 0.01 0.01 0.01
          }
        }
      ]
      name "ds_left"
    }
    DEF DS_RIGHT DistanceSensor {
      translation 0.1 -0.03 0
      rotation 0 0 1 -0.3
      children [
        Shape {
          appearance PBRAppearance {
            baseColor 0.184314 0.596078 0.847059
            roughness 1
            metalness 0
          }
          geometry Box {
            size 0.01 0.01 0.01
          }
        }
      ]
      name "ds_right"
    }
    DEF wheel3 HingeJoint {
      jointParameters HingeJointParameters {
        position 230.765365720566
        axis 0 1 0
        anchor -0.05 0.06 0
      }
      device [
        RotationalMotor {
          name "wheel4"
        }
      ]
      endPoint Solid {
        translation -0.05 -0.0599999999999999 0
        rotation -0.522868107432252 0.6027463285854794 -0.6027485426004283 4.105138201293958
        children [
          DEF WHEEL Shape {
            appearance PBRAppearance {
              baseColor 0.305882 0.898039 0.25098
              roughness 1
              metalness 0
            }
            geometry Cylinder {
              height 0.02
              radius 0.04
              subdivision 24
            }
          }
        ]
        name "solid(2)"
        boundingObject USE WHEEL
        physics Physics {
        }
        linearVelocity 3.2423136727624747e-15 -1.8572428007944639e-16 8.411689918070845e-16
        angularVelocity 3.352656643638527e-15 1.3443259963292545e-13 5.664612520186709e-15
      }
    }
    DEF wheel3 HingeJoint {
      jointParameters HingeJointParameters {
        position 383.03359097790224
        axis 0 1 0
        anchor -0.05 0.06 0
      }
      device [
        RotationalMotor {
          name "wheel3"
        }
      ]
      endPoint Solid {
        translation -0.05 0.06 0
        rotation -0.9856866294419063 0.11920940428465301 -0.11920984216729824 4.69796901200862
        children [
          DEF WHEEL Shape {
            appearance PBRAppearance {
              baseColor 0.305882 0.898039 0.25098
              roughness 1
              metalness 0
            }
            geometry Cylinder {
              height 0.02
              radius 0.04
              subdivision 24
            }
          }
        ]
        name "solid(1)"
        boundingObject USE WHEEL
        physics Physics {
        }
        linearVelocity 5.489330301999945e-16 -4.744730001600865e-16 -5.098870132934952e-16
        angularVelocity 8.776406884470524e-15 1.0735278535575907e-14 5.768520155507021e-15
      }
    }
    DEF WHEEL2 HingeJoint {
      jointParameters HingeJointParameters {
        position 230.7653669429392
        axis 0 1 0
        anchor 0.05 -0.06 0
      }
      device [
        RotationalMotor {
          name "wheel2"
        }
      ]
      endPoint Solid {
        translation 0.05 -0.06 0
        rotation -0.5228685765869964 0.6027461250966264 -0.6027483391091928 4.10513893815804
        children [
          DEF WHEEL Shape {
            appearance PBRAppearance {
              baseColor 0.305882 0.898039 0.25098
              roughness 1
              metalness 0
            }
            geometry Cylinder {
              height 0.02
              radius 0.04
              subdivision 24
            }
          }
        ]
        name "wheel2"
        boundingObject DEF WHEEL Shape {
          appearance PBRAppearance {
            baseColor 0.305882 0.898039 0.25098
            roughness 1
            metalness 0
          }
          geometry Cylinder {
            height 0.02
            radius 0.04
            subdivision 24
          }
        }
        physics Physics {
        }
        linearVelocity 5.322755470928727e-16 -2.6945753868417433e-16 -3.056002633954763e-16
        angularVelocity 8.647285723465123e-15 7.481017535434127e-15 5.595101456315778e-15
      }
    }
    DEF wheel1 HingeJoint {
      jointParameters HingeJointParameters {
        position 383.03358741226054
        axis 0 1 0
        anchor 0.05 0.06 0
      }
      device [
        RotationalMotor {
          name "wheel1"
        }
      ]
      endPoint Solid {
        translation 0.05 0.06 0
        rotation -0.9856862104109914 0.11921113665086566 -0.11921157453883129 4.697968586936836
        children [
          DEF WHEEL Shape {
            appearance PBRAppearance {
              baseColor 0.305882 0.898039 0.25098
              roughness 1
              metalness 0
            }
            geometry Cylinder {
              height 0.02
              radius 0.04
              subdivision 24
            }
          }
        ]
        boundingObject USE WHEEL
        physics Physics {
        }
        linearVelocity 4.2847163251890253e-16 -3.7658434011655696e-16 4.574201342772364e-16
        angularVelocity 9.080022280579753e-15 1.0197529421377051e-14 5.768564840795523e-15
      }
    }
    DEF BODY Shape {
      appearance PBRAppearance {
        baseColor 0.917647 0.145098 0.145098
        roughness 1
        metalness 0
      }
      geometry Box {
        size 0.2 0.1 0.05
      }
    }
  ]
  boundingObject USE BODY
  physics Physics {
    mass 1
  }
  controller "my_controllern"
  linearVelocity 9.948068587892098e-16 -3.382908755165536e-16 -3.979039320256561e-16
  angularVelocity 9.387982903444744e-15 5.492267002800154e-15 3.8615086023707504e-15
}
