#VRML_SIM R2023b utf8

EXTERNPROTO "https://raw.githubusercontent.com/cyberbotics/webots/R2023b/projects/objects/backgrounds/protos/TexturedBackground.proto"
EXTERNPROTO "https://raw.githubusercontent.com/cyberbotics/webots/R2023b/projects/objects/backgrounds/protos/TexturedBackgroundLight.proto"
IMPORTABLE EXTERNPROTO "https://raw.githubusercontent.com/cyberbotics/webots/R2023b/projects/objects/floors/protos/Floor.proto"

WorldInfo {
  basicTimeStep 16
}
Viewpoint {
  orientation 0.2039394214808927 0.07850035542877248 -0.9758311362954121 2.422955999005014
  position 7.201754588050023 6.443783992372531 4.2710864401683075
}
TexturedBackground {
}
TexturedBackgroundLight {
}
Floor {
  size 20 20
}
Robot {
  translation 3.145779062530971 -0.15380445838964368 0.039861748318522676
  rotation -6.318126273669078e-05 3.2305505546762035e-05 0.9999999974822411 0.5103846873684099
  children [
    DEF DS_LEFT DistanceSensor {
      translation 0.1 0.03 0
      rotation 0 0 1 0.3
      children [
        Shape {
          appearance PBRAppearance {
            baseColor 0.184314 0.596078 0.847059
            roughness 1
            metalness 0
          }
          geometry Box {
            size 0.01 0.01 0.01
          }
        }
      ]
      name "ds_left"
    }
    DEF DS_RIGHT DistanceSensor {
      translation 0.1 -0.03 0
      rotation 0 0 1 -0.3
      children [
        Shape {
          appearance PBRAppearance {
            baseColor 0.184314 0.596078 0.847059
            roughness 1
            metalness 0
          }
          geometry Box {
            size 0.01 0.01 0.01
          }
        }
      ]
      name "ds_right"
    }
    DEF wheel3 HingeJoint {
      jointParameters HingeJointParameters {
        position 216.78436461470744
        axis 0 1 0
        anchor -0.05 0.06 0
      }
      device [
        RotationalMotor {
          name "wheel4"
        }
      ]
      endPoint Solid {
        translation -0.05 -0.059999999999999915 0
        rotation -0.005116485626049331 0.7070962269966853 -0.7070988243109239 3.1518254979621867
        children [
          DEF WHEEL Shape {
            appearance PBRAppearance {
              baseColor 0.305882 0.898039 0.25098
              roughness 1
              metalness 0
            }
            geometry Cylinder {
              height 0.02
              radius 0.04
              subdivision 24
            }
          }
        ]
        name "solid(2)"
        boundingObject USE WHEEL
        physics Physics {
        }
        linearVelocity 0.1495653104913532 0.09580767446054654 -8.640038943760136e-08
        angularVelocity -2.0812135036806008 3.705550882181786 -0.15450166432670304
      }
    }
    DEF wheel3 HingeJoint {
      jointParameters HingeJointParameters {
        position 374.49254454761564
        axis 0 1 0
        anchor -0.05 0.06 0
      }
      device [
        RotationalMotor {
          name "wheel3"
        }
      ]
      endPoint Solid {
        translation -0.05 0.06 0
        rotation 0.2292414157428503 -0.6882749788910735 0.6882775070716072 2.6908986588306867
        children [
          DEF WHEEL Shape {
            appearance PBRAppearance {
              baseColor 0.305882 0.898039 0.25098
              roughness 1
              metalness 0
            }
            geometry Cylinder {
              height 0.02
              radius 0.04
              subdivision 24
            }
          }
        ]
        name "solid(1)"
        boundingObject USE WHEEL
        physics Physics {
        }
        linearVelocity 0.16555368314422597 0.10478775464808344 9.079943514990084e-08
        angularVelocity -2.4486652264616016 4.359367650758182 -0.15503885841759882
      }
    }
    DEF WHEEL2 HingeJoint {
      jointParameters HingeJointParameters {
        position 216.78435247107421
        axis 0 1 0
        anchor 0.05 -0.06 0
      }
      device [
        RotationalMotor {
          name "wheel2"
        }
      ]
      endPoint Solid {
        translation 0.05 -0.06 0
        rotation -0.005112192184552419 0.7070962425254029 -0.707098839836076 3.151816911339367
        children [
          DEF WHEEL Shape {
            appearance PBRAppearance {
              baseColor 0.305882 0.898039 0.25098
              roughness 1
              metalness 0
            }
            geometry Cylinder {
              height 0.02
              radius 0.04
              subdivision 24
            }
          }
        ]
        name "wheel2"
        boundingObject DEF WHEEL Shape {
          appearance PBRAppearance {
            baseColor 0.305882 0.898039 0.25098
            roughness 1
            metalness 0
          }
          geometry Cylinder {
            height 0.02
            radius 0.04
            subdivision 24
          }
        }
        physics Physics {
        }
        linearVelocity 0.15704516524752424 0.08248317586020212 1.6375557285906726e-07
        angularVelocity -2.081213752172123 3.7055494805892972 -0.15449952080699775
      }
    }
    DEF wheel1 HingeJoint {
      jointParameters HingeJointParameters {
        position 374.49253405423354
        axis 0 1 0
        anchor 0.05 0.06 0
      }
      device [
        RotationalMotor {
          name "wheel1"
        }
      ]
      endPoint Solid {
        translation 0.05 0.06 0
        rotation 0.22923761476118534 -0.688275611873372 0.6882781400559935 2.6909058812279154
        children [
          DEF WHEEL Shape {
            appearance PBRAppearance {
              baseColor 0.305882 0.898039 0.25098
              roughness 1
              metalness 0
            }
            geometry Cylinder {
              height 0.02
              radius 0.04
              subdivision 24
            }
          }
        ]
        boundingObject USE WHEEL
        physics Physics {
        }
        linearVelocity 0.17303599283048796 0.09146201929852489 -1.6452438349863968e-07
        angularVelocity -2.4486643882810335 4.359366846554412 -0.1550379825570716
      }
    }
    DEF BODY Shape {
      appearance PBRAppearance {
        baseColor 0.917647 0.145098 0.145098
        roughness 1
        metalness 0
      }
      geometry Box {
        size 0.2 0.1 0.05
      }
    }
  ]
  boundingObject USE BODY
  physics Physics {
    mass 1
  }
  controller "my_controller"
  linearVelocity 0.1612994235730195 0.09363546781350215 1.2980489776736747e-07
  angularVelocity -3.7080873061557037e-06 9.044703152605652e-07 -0.15282492631922012
}
