#VRML_SIM R2023b utf8

EXTERNPROTO "https://raw.githubusercontent.com/cyberbotics/webots/R2023b/projects/objects/backgrounds/protos/TexturedBackground.proto"
EXTERNPROTO "https://raw.githubusercontent.com/cyberbotics/webots/R2023b/projects/objects/backgrounds/protos/TexturedBackgroundLight.proto"
IMPORTABLE EXTERNPROTO "https://raw.githubusercontent.com/cyberbotics/webots/R2023b/projects/objects/floors/protos/Floor.proto"

WorldInfo {
  basicTimeStep 16
}
Viewpoint {
  orientation -0.31023029754411346 0.24852020322672805 0.9176027850185703 1.8738395723668624
  position 0.2875073441979752 -1.4596801761626237 0.8665909098965705
}
TexturedBackground {
}
TexturedBackgroundLight {
}
Floor {
  size 1 1
}
DEF WALL_1 Solid {
  translation 0.5 0 0.05
  children [
    DEF WALL_SHAPE Shape {
      appearance PBRAppearance {
        roughness 1
        metalness 0
      }
      geometry Box {
        size 0.1 1.1 0.1
      }
    }
  ]
  boundingObject USE WALL_SHAPE
}
Solid {
  translation -0.5 0 0.05
  children [
    USE WALL_SHAPE
  ]
  name "wall2"
  boundingObject USE WALL_SHAPE
}
Solid {
  translation 0 -0.5 0.05
  rotation 0 0 1 1.5708
  children [
    USE WALL_SHAPE
  ]
  name "wall3"
  boundingObject USE WALL_SHAPE
}
Solid {
  translation 0 0.5 0.05
  rotation 0 0 1 1.5708
  children [
    USE WALL_SHAPE
  ]
  name "solid(3)"
  boundingObject USE WALL_SHAPE
}
Robot {
  translation 0.10191051769611041 0.11777131998644878 0.03986048263104666
  rotation -2.4464842886359764e-08 -1.2382346924148472e-07 -0.999999999999992 2.17252338409276
  children [
    DEF DS_LEFT DistanceSensor {
      translation 0.1 0.03 0
      rotation 0 0 1 0.3
      children [
        Shape {
          appearance PBRAppearance {
            baseColor 0.184314 0.596078 0.847059
            roughness 1
            metalness 0
          }
          geometry Box {
            size 0.01 0.01 0.01
          }
        }
      ]
      name "ds_left"
    }
    DEF DS_RIGHT DistanceSensor {
      translation 0.1 -0.03 0
      rotation 0 0 1 -0.3
      children [
        Shape {
          appearance PBRAppearance {
            baseColor 0.184314 0.596078 0.847059
            roughness 1
            metalness 0
          }
          geometry Box {
            size 0.01 0.01 0.01
          }
        }
      ]
      name "ds_right"
    }
    DEF wheel3 HingeJoint {
      jointParameters HingeJointParameters {
        position 14.574516569268829
        axis 0 1 0
        anchor -0.05 0.06 0
      }
      device [
        RotationalMotor {
          name "wheel4"
        }
      ]
      endPoint Solid {
        translation -0.05 -0.059999999999999984 0
        rotation 0.4103434728163842 0.6448314429417377 -0.6448338115442348 2.3628127544570763
        children [
          DEF WHEEL Shape {
            appearance PBRAppearance {
              baseColor 0.305882 0.898039 0.25098
              roughness 1
              metalness 0
            }
            geometry Cylinder {
              height 0.02
              radius 0.04
              subdivision 24
            }
          }
        ]
        name "solid(2)"
        boundingObject USE WHEEL
        physics Physics {
        }
        linearVelocity -0.02264268080269953 -0.03297436626358184 -4.310503070802191e-09
        angularVelocity 0.8243591837766628 -0.5660670770725956 -1.050268605488094e-07
      }
    }
    DEF wheel3 HingeJoint {
      jointParameters HingeJointParameters {
        position 40.17393732599325
        axis 0 1 0
        anchor -0.05 0.06 0
      }
      device [
        RotationalMotor {
          name "wheel3"
        }
      ]
      endPoint Solid {
        translation -0.05 0.06 0
        rotation 0.23785087696381538 0.6868127455598135 -0.686815268368529 2.674570474355324
        children [
          DEF WHEEL Shape {
            appearance PBRAppearance {
              baseColor 0.305882 0.898039 0.25098
              roughness 1
              metalness 0
            }
            geometry Cylinder {
              height 0.02
              radius 0.04
              subdivision 24
            }
          }
        ]
        name "solid(1)"
        boundingObject USE WHEEL
        physics Physics {
        }
        linearVelocity -0.022642683287249537 -0.03297436988129501 4.30969979961279e-09
        angularVelocity 0.8243591734347786 -0.5660670927517152 1.288592990361823e-07
      }
    }
    DEF WHEEL2 HingeJoint {
      jointParameters HingeJointParameters {
        position 14.574515196703771
        axis 0 1 0
        anchor 0.05 -0.06 0
      }
      device [
        RotationalMotor {
          name "wheel2"
        }
      ]
      endPoint Solid {
        translation 0.05 -0.06 0
        rotation 0.41034398986940324 0.6448312784268747 -0.6448336470287677 2.3628118693840827
        children [
          DEF WHEEL Shape {
            appearance PBRAppearance {
              baseColor 0.305882 0.898039 0.25098
              roughness 1
              metalness 0
            }
            geometry Cylinder {
              height 0.02
              radius 0.04
              subdivision 24
            }
          }
        ]
        name "wheel2"
        boundingObject DEF WHEEL Shape {
          appearance PBRAppearance {
            baseColor 0.305882 0.898039 0.25098
            roughness 1
            metalness 0
          }
          geometry Cylinder {
            height 0.02
            radius 0.04
            subdivision 24
          }
        }
        physics Physics {
        }
        linearVelocity -0.02264268381581972 -0.03297436419342771 -4.311113055139937e-09
        angularVelocity 0.824359173140346 -0.5660670925620876 1.2886219066139592e-07
      }
    }
    DEF wheel1 HingeJoint {
      jointParameters HingeJointParameters {
        position 40.1739356856975
        axis 0 1 0
        anchor 0.05 0.06 0
      }
      device [
        RotationalMotor {
          name "wheel1"
        }
      ]
      endPoint Solid {
        translation 0.05 0.06 0
        rotation 0.23785147212073143 0.6868126425053326 -0.6868151653136695 2.6745693477793813
        children [
          DEF WHEEL Shape {
            appearance PBRAppearance {
              baseColor 0.305882 0.898039 0.25098
              roughness 1
              metalness 0
            }
            geometry Cylinder {
              height 0.02
              radius 0.04
              subdivision 24
            }
          }
        ]
        boundingObject USE WHEEL
        physics Physics {
        }
        linearVelocity -0.02264268630059056 -0.0329743678121011 4.311050126562462e-09
        angularVelocity 0.8243591734166024 -0.5660670927781826 1.288778083792157e-07
      }
    }
    DEF BODY Shape {
      appearance PBRAppearance {
        baseColor 0.917647 0.145098 0.145098
        roughness 1
        metalness 0
      }
      geometry Box {
        size 0.2 0.1 0.05
      }
    }
  ]
  boundingObject USE BODY
  physics Physics {
    mass 1
  }
  controller "my_controller"
  linearVelocity -0.022642683551508464 -0.03297436703748313 -7.167157099984706e-13
  angularVelocity -4.1497496820890463e-08 -6.040816592467932e-08 -4.425975460040202e-08
}
